<?xml version="1.0"?>
<robot xmlns:xacro="http://www.ros.org/wiki/xacro" name="first_robot">

    <xacro:include filename="inertial_macros.xacro"     />

    <material name="grey">
        <color rgba="0.5 0.5 0.5 1" />  
    </material>

    <material name="green">
        <color rgba="0 0.7 0 1" />
    </material>

    <material name="blue">
        <color rgba="0 0 0.7 1" />
    </material>

    <material name="white">
        <color rgba="1 1 1 1" />
    </material>


    <link name="base_link">
        <visual>
            <geometry>
                <box size="0.6 0.4 0.2" />
            </geometry>
            <origin xyz="0.0 0.0 0.1" rpy="0.0 0.0 0.0" />  
            <material name="green" />     
        </visual>
        <collision>
            <geometry>
                <box size="0.6 0.4 0.2" />
            </geometry>
            <origin xyz="0.0 0.0 0.1" rpy="0.0 0.0 0.0" />      
        </collision>
        <xacro:inertial_box mass="0.5" x="0.6" y="0.4" z="0.2">
            <origin xyz = "0.0 0.0 0.1" rpy= "0.0 0.0 0.0"/>
        </xacro:inertial_box>      
    </link>


    <link name="lidar_link">
        <visual>
            <geometry>
                <cylinder radius="0.1" length="0.05"/>   
            </geometry>
            <origin xyz="0 0 0" rpy= "0 0 0" />
            <material name="blue" />
        </visual>
        <collision>
            <geometry>
                <box size="0.2 0.2 0.05"/> 
            </geometry>
            <origin xyz="0 0 0" rpy= "0 0 0" />
        </collision>
        <xacro:inertial_box mass="0.1" x="0.2" y="0.2" z="0.05">
            <origin xyz="0 0 0" rpy="0 0 0" />
        </xacro:inertial_box>
    </link>

    
    <link name="left_wheel_link">
        <visual>
            <geometry>
                <cylinder radius="0.15" length="0.05"/>
            </geometry>
            <origin xyz="0.0 0.0 0.0" rpy="0 0 0" />
            <material name="white" />
        </visual> 
        <collision>
            <geometry>
                <cylinder radius="0.15" length="0.05"/>
            </geometry>
            <origin xyz="0.0 0.0 0.0" rpy="0 0 0" />
        </collision>
        <xacro:inertial_cylinder mass="0.1" length="0.05" radius="0.15">
            <origin xyz="0 0 0" rpy="0 0 0"/>
        </xacro:inertial_cylinder>
    </link>


    <link name="right_wheel_link">
        <visual>
            <geometry>
                <cylinder radius="0.15" length="0.05"/>
            </geometry>
            <origin xyz="0 0 0" rpy="0 0 0" />
            <material name="white" />    
        </visual>
        <collision>
            <geometry>
                <cylinder radius="0.15" length="0.05"/>
            </geometry>
            <origin xyz="0 0 0" rpy="0 0 0" />
        </collision>
        <xacro:inertial_cylinder mass="0.1" length="0.05" radius="0.15">
            <origin xyz="0 0 0" rpy="0 0 0"/>
        </xacro:inertial_cylinder>
    </link>


    <link name="caster_wheel_link">
        <visual>
            <geometry>
                <sphere radius="0.05"/>
            </geometry>
            <origin xyz="0 0 0" rpy="0 0 0" />
            <material name="white" />
        </visual>
        <collision>
            <geometry>
                <sphere radius="0.05"/>
            </geometry>
            <origin xyz="0 0 0" rpy="0 0 0" />
        </collision>
        <xacro:inertial_sphere mass="0.1" radius="0.05">
            <origin xyz="0 0 0" rpy="0 0 0"/>
        </xacro:inertial_sphere>
    </link>

    <link name="base_footprint" />

    <joint name="base_lidar_joint" type="fixed">
        <parent link="base_link"/>
        <child link="lidar_link"/>
        <origin xyz="0 0 0.225" rpy="0 0 0" />
    </joint>

    <joint name="base_left_wheel_joint" type="continuous">
        <parent link="base_link"/>
        <child link="left_wheel_link"/>
        <origin xyz="-0.15 0.225 0.05" rpy="-1.5708 0 0" />
        <axis xyz="0 0 1"/>
    </joint>

    <joint name="base_right_wheel_joint" type="continuous">
        <parent link="base_link"/>
        <child link="right_wheel_link"/>
        <origin xyz="-0.15 -0.225 0.05" rpy="1.5708 0 0" />
        <axis xyz="0 0 1"/>
    </joint>

    <joint name="base_caster_wheel_joint" type="fixed">
        <parent link = "base_link"/>
        <child link = "caster_wheel_link"/>
        <origin xyz="0.2 0 -0.025" rpy="0 0 0"/>
    </joint>

    <joint name="base_footprint_joint" type="fixed">
        <parent link="base_footprint"/>
        <child link="base_link"/>
        <origin xyz="0 0 0.05" rpy="0 0 0"/>
    </joint>
</robot>
